<?xml version="1.0" ?>
<!-- =================================================================================== -->
<!-- |    This document was autogenerated by xacro from simple_grace.xacro             | -->
<!-- |    EDITING THIS FILE BY HAND IS NOT RECOMMENDED                                 | -->
<!-- =================================================================================== -->
<robot name="single_leg">
    <link name="grace"/>
    <link name="LF-HAA">
        <inertial>
            <origin rpy="0. 0 0." xyz="0. 0. 0."/>
            <mass value="1.277375"/>
            <inertia ixx="1" ixy="0" ixz="0" iyy="1" iyz="0" izz="1"/>
        </inertial>
        <visual>
            <origin rpy="0 -1.5707963267948966 0" xyz="-0.05 0 0"/>
            <geometry>
                <cylinder length="0.1" radius="0.04"/>
            </geometry>
        </visual>
        <collision>
            <origin rpy="0 -1.5707963267948966 0" xyz="-0.05 0 0"/>
            <geometry>
                <cylinder length="0.1" radius="0.04"/>
            </geometry>
        </collision>
    </link>
    <link name="LF-HFE">
        <inertial>
            <origin rpy="0. 0. 0." xyz="0. 0. 0."/>
            <mass value="0.4005713"/>
            <inertia ixx="1" ixy="0" ixz="0" iyy="1" iyz="0" izz="1"/>
        </inertial>
        <visual>
            <origin rpy="1.5707963267948966 0 0" xyz="0.0 0.15 0.0"/>
            <geometry>
                <cylinder length="0.30" radius="0.025"/>
            </geometry>
        </visual>
        <collision>
            <origin rpy="1.5707963267948966 0 0" xyz="0.0 0.15 0.0"/>
            <geometry>
                <cylinder length="0.30" radius="0.025"/>
            </geometry>
        </collision>
    </link>
    <link name="LF-KFE">
        <inertial>
            <origin rpy="0. 0. 0." xyz="0. 0. 0."/>
            <mass value="0.4023528"/>
            <inertia ixx="1" ixy="0." ixz="0." iyy="1" iyz="0." izz="1"/>
        </inertial>
        <visual>
            <origin rpy="1.5707963267948966 0 0" xyz="0 0.15 0"/>
            <geometry>
                <cylinder length="0.3" radius="0.015"/>
            </geometry>
        </visual>
        <collision>
            <origin rpy="1.5707963267948966 0 0" xyz="0 0.15 0"/>
            <geometry>
                <cylinder length="0.3" radius="0.015"/>
            </geometry>
        </collision>
    </link>
    <link name="LF-FOOT">
        <inertial>
            <origin rpy="0. 0. 0." xyz="0. 0. 0."/>
            <mass value="0.3656907"/>
            <inertia ixx="1" ixy="0" ixz="0" iyy="1" iyz="0" izz="1"/>
        </inertial>
        <visual>
            <origin rpy="0 0 0" xyz="0 0 0"/>
            <geometry>
                <sphere radius="0.02"/>
            </geometry>
        </visual>
    </link>

    <joint name="grace_LF-HAA" type="revolute">
        <origin rpy="0 0 0" xyz="0 0 0"/>
        <parent link="grace"/>
        <child link="LF-HAA"/>
        <axis xyz="0 0 1"/>
        <limit effort="4800." lower="-3.141592653589793" upper="3.141592653589793" velocity="7.4874625"/>
    </joint>
    <joint name="LF-HAA_LF-HFE" type="revolute">
        <origin rpy="1.5707963267948966 -1.5707963267948966 0" xyz="-0.1 0 0"/>
        <parent link="LF-HAA"/>
        <child link="LF-HFE"/>
        <axis xyz="0 0 1"/>
        <limit effort="4800." lower="-3.141592653589793" upper="3.141592653589793" velocity="7.4874625"/>
    </joint>
    <joint name="LF-HFE_LF-KFE" type="revolute">
        <origin rpy="0 0 0" xyz="0 0.30 0"/>
        <parent link="LF-HFE"/>
        <child link="LF-KFE"/>
        <axis xyz="0 0 1"/>
        <limit effort="4800." lower="-3.141592653589793" upper="3.141592653589793" velocity="7.4874625"/>
    </joint>
    <joint name="LF-KFE_LF-FOOT" type="fixed">
        <origin rpy="0 0 0" xyz="0 0.31 0"/>
        <parent link="LF-KFE"/>
        <child link="LF-FOOT"/>
    </joint>

</robot>