<?xml version="1.0" ?>
<!-- =================================================================================== -->
<!-- |    This document was autogenerated by xacro from simple_grace.xacro             | -->
<!-- |    EDITING THIS FILE BY HAND IS NOT RECOMMENDED                                 | -->
<!-- =================================================================================== -->
<robot name="grace">
  <link name="grace">
    <inertial>
      <origin rpy="0. 0 0." xyz="0. 0. 0."/>
      <mass value="1.0"/>
      <inertia ixx="0" ixy="0" ixz="0" iyy="0" iyz="0" izz="0"/>
    </inertial>
    <visual>
      <origin rpy="0 0 0" xyz="0 0 0"/>
      <geometry>
        <box size="0.4 0.8 0.2"/>
      </geometry>
    </visual>
    <collision>
      <origin rpy="0 0 0" xyz="0 0 0"/>
      <geometry>
        <box size="0.4 0.8 0.2"/>
      </geometry>
    </collision>
  </link>
  <link name="LF-HAA">
    <inertial>
      <origin rpy="0. 0 0." xyz="0. 0. 0."/>
      <mass value="1.277375"/>
      <inertia ixx="0" ixy="0" ixz="0" iyy="0" iyz="0" izz="0"/>
    </inertial>
    <visual>
      <origin rpy="0 -1.5707963267948966 0" xyz="-0.05 0 0"/>
      <geometry>
        <cylinder length="0.1" radius="0.04"/>
      </geometry>
    </visual>
    <collision>
      <origin rpy="0 -1.5707963267948966 0" xyz="-0.05 0 0"/>
      <geometry>
        <cylinder length="0.1" radius="0.04"/>
      </geometry>
    </collision>
  </link>
  <link name="LR-HAA">
    <inertial>
      <origin rpy="0. 0. 0." xyz="0. 0. 0."/>
      <mass value="1.277375"/>
      <inertia ixx="0." ixy="0." ixz="0." iyy="0." iyz="0." izz="0."/>
    </inertial>
    <visual>
      <origin rpy="0 -1.5707963267948966 0" xyz="-0.05 0 0"/>
      <geometry>
        <cylinder length="0.1" radius="0.04"/>
      </geometry>
    </visual>
    <collision>
      <origin rpy="0 -1.5707963267948966 0" xyz="-0.05 0 0"/>
      <geometry>
        <cylinder length="0.1" radius="0.04"/>
      </geometry>
    </collision>
  </link>
  <link name="RR-HAA">
    <inertial>
      <origin rpy="0. 0. 0." xyz="0. 0. 0."/>
      <mass value="1.277375"/>
      <inertia ixx="0." ixy="0." ixz="0." iyy="0." iyz="0." izz="0."/>
    </inertial>
    <visual>
      <origin rpy="0 -1.5707963267948966 0" xyz="0.05 0 0"/>
      <geometry>
        <cylinder length="0.1" radius="0.04"/>
      </geometry>
    </visual>
    <collision>
      <origin rpy="0 -1.5707963267948966 0" xyz="0.05 0 0"/>
      <geometry>
        <cylinder length="0.1" radius="0.04"/>
      </geometry>
    </collision>
  </link>
  <link name="RF-HAA">
    <inertial>
      <origin rpy="0. 0. 0." xyz="0. 0. 0."/>
      <mass value="1.277375"/>
      <inertia ixx="0." ixy="0." ixz="0." iyy="0." iyz="0." izz="0."/>
    </inertial>
    <visual>
      <origin rpy="0 -1.5707963267948966 0" xyz="0.05 0 0"/>
      <geometry>
        <cylinder length="0.1" radius="0.04"/>
      </geometry>
    </visual>
    <collision>
      <origin rpy="0 -1.5707963267948966 0" xyz="0.05 0 0"/>
      <geometry>
        <cylinder length="0.1" radius="0.04"/>
      </geometry>
    </collision>
  </link>
  <joint name="grace_LF-HAA" type="revolute">
    <origin rpy="0 0 0" xyz="-0.2 0.4 0"/>
    <parent link="grace"/>
    <child link="LF-HAA"/>
    <axis xyz="0 0 1"/>
    <limit effort="4800." lower="-3.141592653589793" upper="3.141592653589793" velocity="7.4874625"/>
  </joint>
  <joint name="grace_LR-HAA" type="revolute">
    <origin rpy="0 0 0 " xyz="-0.2 -0.4 0"/>
    <parent link="grace"/>
    <child link="LR-HAA"/>
    <axis xyz="0 0 1"/>
    <limit effort="4800." lower="-3.141592653589793" upper="3.141592653589793" velocity="7.4874625"/>
  </joint>
  <joint name="grace_RR-HAA" type="revolute">
    <origin rpy="0 0 0 " xyz="0.2 -0.4 0"/>
    <parent link="grace"/>
    <child link="RR-HAA"/>
    <axis xyz="0 0 1"/>
    <limit effort="4800." lower="-3.141592653589793" upper="3.141592653589793" velocity="7.4874625"/>
  </joint>
  <joint name="grace_RF-HAA" type="revolute">
    <origin rpy="0 0 0 " xyz="0.2 0.4 0"/>
    <parent link="grace"/>
    <child link="RF-HAA"/>
    <axis xyz="0 0 1"/>
    <limit effort="4800." lower="-3.141592653589793" upper="3.141592653589793" velocity="7.4874625"/>
  </joint>
  <link name="LF-HFE">
    <inertial>
      <origin rpy="0. 0. 0." xyz="0. 0. 0."/>
      <mass value="0.4005713"/>
      <inertia ixx="0." ixy="0." ixz="0." iyy="0." iyz="0." izz="0."/>
    </inertial>
    <visual>
      <origin rpy="1.5707963267948966 0 0" xyz="0.0 0.1515 0.0"/>
      <geometry>
        <cylinder length="0.303" radius="0.025"/>
      </geometry>
    </visual>
    <collision>
      <origin rpy="1.5707963267948966 0 0" xyz="0.0 0.1515 0.0"/>
      <geometry>
        <cylinder length="0.303" radius="0.025"/>
      </geometry>
    </collision>
  </link>
  <link name="LF-KFE">
    <inertial>
      <origin rpy="0. 0. 0." xyz="0. 0. 0."/>
      <mass value="0.4023528"/>
      <inertia ixx="0." ixy="0." ixz="0." iyy="0." iyz="0." izz="0."/>
    </inertial>
    <visual>
      <origin rpy="1.5707963267948966 0 0" xyz="0 0.15 0"/>
      <geometry>
        <cylinder length="0.3" radius="0.015"/>
      </geometry>
    </visual>
    <collision>
      <origin rpy="1.5707963267948966 0 0" xyz="0 0.15 0"/>
      <geometry>
        <cylinder length="0.13" radius="0.015"/>
      </geometry>
    </collision>
  </link>
  <link name="LF-FOOT">
    <inertial>
      <origin rpy="0. 0. 0." xyz="0. 0. 0."/>
      <mass value="0.3656907"/>
      <inertia ixx="0." ixy="0." ixz="0." iyy="0." iyz="0." izz="0."/>
    </inertial>
    <visual>
      <origin rpy="0 0 0" xyz="0 0 0"/>
      <geometry>
        <sphere radius="0.02"/>
      </geometry>
    </visual>
  </link>
  <joint name="LF-HFE_LF-KFE" type="revolute">
    <origin rpy="0 0 0" xyz="0 0.303 0"/>
    <parent link="LF-HFE"/>
    <child link="LF-KFE"/>
    <axis xyz="0 0 1"/>
    <limit effort="4800." lower="-3.141592653589793" upper="3.141592653589793" velocity="7.4874625"/>
  </joint>
  <joint name="LF-KFE_LF-FOOT" type="fixed">
    <origin rpy="0 0 0" xyz="0 0.31 0"/>
    <parent link="LF-KFE"/>
    <child link="LF-FOOT"/>
  </joint>
  <link name="LR-HFE">
    <inertial>
      <origin rpy="0. 0. 0." xyz="0. 0. 0."/>
      <mass value="0.4005713"/>
      <inertia ixx="0." ixy="0." ixz="0." iyy="0." iyz="0." izz="0."/>
    </inertial>
    <visual>
      <origin rpy="1.5707963267948966 0 0" xyz="0.0 0.1515 0.0"/>
      <geometry>
        <cylinder length="0.303" radius="0.025"/>
      </geometry>
    </visual>
    <collision>
      <origin rpy="1.5707963267948966 0 0" xyz="0.0 0.1515 0.0"/>
      <geometry>
        <cylinder length="0.303" radius="0.025"/>
      </geometry>
    </collision>
  </link>
  <link name="LR-KFE">
    <inertial>
      <origin rpy="0. 0. 0." xyz="0. 0. 0."/>
      <mass value="0.4023528"/>
      <inertia ixx="0." ixy="0." ixz="0." iyy="0." iyz="0." izz="0."/>
    </inertial>
    <visual>
      <origin rpy="1.5707963267948966 0 0" xyz="0 0.15 0"/>
      <geometry>
        <cylinder length="0.3" radius="0.015"/>
      </geometry>
    </visual>
    <collision>
      <origin rpy="1.5707963267948966 0 0" xyz="0 0.15 0"/>
      <geometry>
        <cylinder length="0.13" radius="0.015"/>
      </geometry>
    </collision>
  </link>
  <link name="LR-FOOT">
    <inertial>
      <origin rpy="0. 0. 0." xyz="0. 0. 0."/>
      <mass value="0.3656907"/>
      <inertia ixx="0." ixy="0." ixz="0." iyy="0." iyz="0." izz="0."/>
    </inertial>
    <visual>
      <origin rpy="0 0 0" xyz="0 0 0"/>
      <geometry>
        <sphere radius="0.02"/>
      </geometry>
    </visual>
  </link>
  <joint name="LR-HFE_LR-KFE" type="revolute">
    <origin rpy="0 0 0" xyz="0 0.303 0"/>
    <parent link="LR-HFE"/>
    <child link="LR-KFE"/>
    <axis xyz="0 0 1"/>
    <limit effort="4800." lower="-3.141592653589793" upper="3.141592653589793" velocity="7.4874625"/>
  </joint>
  <joint name="LR-KFE_LR-FOOT" type="fixed">
    <origin rpy="0 0 0" xyz="0 0.31 0"/>
    <parent link="LR-KFE"/>
    <child link="LR-FOOT"/>
  </joint>
  <link name="RR-HFE">
    <inertial>
      <origin rpy="0. 0. 0." xyz="0. 0. 0."/>
      <mass value="0.4005713"/>
      <inertia ixx="0." ixy="0." ixz="0." iyy="0." iyz="0." izz="0."/>
    </inertial>
    <visual>
      <origin rpy="1.5707963267948966 0 0" xyz="0.0 0.1515 0.0"/>
      <geometry>
        <cylinder length="0.303" radius="0.025"/>
      </geometry>
    </visual>
    <collision>
      <origin rpy="1.5707963267948966 0 0" xyz="0.0 0.1515 0.0"/>
      <geometry>
        <cylinder length="0.303" radius="0.025"/>
      </geometry>
    </collision>
  </link>
  <link name="RR-KFE">
    <inertial>
      <origin rpy="0. 0. 0." xyz="0. 0. 0."/>
      <mass value="0.4023528"/>
      <inertia ixx="0." ixy="0." ixz="0." iyy="0." iyz="0." izz="0."/>
    </inertial>
    <visual>
      <origin rpy="1.5707963267948966 0 0" xyz="0 0.15 0"/>
      <geometry>
        <cylinder length="0.3" radius="0.015"/>
      </geometry>
    </visual>
    <collision>
      <origin rpy="1.5707963267948966 0 0" xyz="0 0.15 0"/>
      <geometry>
        <cylinder length="0.13" radius="0.015"/>
      </geometry>
    </collision>
  </link>
  <link name="RR-FOOT">
    <inertial>
      <origin rpy="0. 0. 0." xyz="0. 0. 0."/>
      <mass value="0.3656907"/>
      <inertia ixx="0." ixy="0." ixz="0." iyy="0." iyz="0." izz="0."/>
    </inertial>
    <visual>
      <origin rpy="0 0 0" xyz="0 0 0"/>
      <geometry>
        <sphere radius="0.02"/>
      </geometry>
    </visual>
  </link>
  <joint name="RR-HFE_RR-KFE" type="revolute">
    <origin rpy="0 0 0" xyz="0 0.303 0"/>
    <parent link="RR-HFE"/>
    <child link="RR-KFE"/>
    <axis xyz="0 0 1"/>
    <limit effort="4800." lower="-3.141592653589793" upper="3.141592653589793" velocity="7.4874625"/>
  </joint>
  <joint name="RR-KFE_RR-FOOT" type="fixed">
    <origin rpy="0 0 0" xyz="0 0.31 0"/>
    <parent link="RR-KFE"/>
    <child link="RR-FOOT"/>
  </joint>
  <link name="RF-HFE">
    <inertial>
      <origin rpy="0. 0. 0." xyz="0. 0. 0."/>
      <mass value="0.4005713"/>
      <inertia ixx="0." ixy="0." ixz="0." iyy="0." iyz="0." izz="0."/>
    </inertial>
    <visual>
      <origin rpy="1.5707963267948966 0 0" xyz="0.0 0.1515 0.0"/>
      <geometry>
        <cylinder length="0.303" radius="0.025"/>
      </geometry>
    </visual>
    <collision>
      <origin rpy="1.5707963267948966 0 0" xyz="0.0 0.1515 0.0"/>
      <geometry>
        <cylinder length="0.303" radius="0.025"/>
      </geometry>
    </collision>
  </link>
  <link name="RF-KFE">
    <inertial>
      <origin rpy="0. 0. 0." xyz="0. 0. 0."/>
      <mass value="0.4023528"/>
      <inertia ixx="0." ixy="0." ixz="0." iyy="0." iyz="0." izz="0."/>
    </inertial>
    <visual>
      <origin rpy="1.5707963267948966 0 0" xyz="0 0.15 0"/>
      <geometry>
        <cylinder length="0.3" radius="0.015"/>
      </geometry>
    </visual>
    <collision>
      <origin rpy="1.5707963267948966 0 0" xyz="0 0.15 0"/>
      <geometry>
        <cylinder length="0.13" radius="0.015"/>
      </geometry>
    </collision>
  </link>
  <link name="RF-FOOT">
    <inertial>
      <origin rpy="0. 0. 0." xyz="0. 0. 0."/>
      <mass value="0.3656907"/>
      <inertia ixx="0." ixy="0." ixz="0." iyy="0." iyz="0." izz="0."/>
    </inertial>
    <visual>
      <origin rpy="0 0 0" xyz="0 0 0"/>
      <geometry>
        <sphere radius="0.02"/>
      </geometry>
    </visual>
  </link>
  <joint name="RF-HFE_RF-KFE" type="revolute">
    <origin rpy="0 0 0" xyz="0 0.303 0"/>
    <parent link="RF-HFE"/>
    <child link="RF-KFE"/>
    <axis xyz="0 0 1"/>
    <limit effort="4800." lower="-3.141592653589793" upper="3.141592653589793" velocity="7.4874625"/>
  </joint>
  <joint name="RF-KFE_RF-FOOT" type="fixed">
    <origin rpy="0 0 0" xyz="0 0.31 0"/>
    <parent link="RF-KFE"/>
    <child link="RF-FOOT"/>
  </joint>
  <joint name="LF-HAA_LF-HFE" type="revolute">
    <origin rpy="1.5707963267948966 -1.5707963267948966 0" xyz="-0.1 0 0"/>
    <parent link="LF-HAA"/>
    <child link="LF-HFE"/>
    <axis xyz="0 0 1"/>
    <limit effort="4800." lower="-3.141592653589793" upper="3.141592653589793" velocity="7.4874625"/>
  </joint>
  <joint name="LR-HAA_LR-HFE" type="revolute">
    <origin rpy="1.5707963267948966 -1.5707963267948966 0" xyz="-0.1 0 0"/>
    <parent link="LR-HAA"/>
    <child link="LR-HFE"/>
    <axis xyz="0 0 1"/>
    <limit effort="4800." lower="-3.141592653589793" upper="3.141592653589793" velocity="7.4874625"/>
  </joint>
  <joint name="RR-HAA_RR-HFE" type="revolute">
    <origin rpy="-1.5707963267948966 -1.5707963267948966 0" xyz="0.1 0 0"/>
    <parent link="RR-HAA"/>
    <child link="RR-HFE"/>
    <axis xyz="0 0 1"/>
    <limit effort="4800." lower="-3.141592653589793" upper="3.141592653589793" velocity="7.4874625"/>
  </joint>
  <joint name="RF-HAA_RL-HFE" type="revolute">
    <origin rpy="-1.5707963267948966 -1.5707963267948966 0" xyz="0.1 0 0"/>
    <parent link="RF-HAA"/>
    <child link="RF-HFE"/>
    <axis xyz="0 0 1"/>
    <limit effort="4800." lower="-3.141592653589793" upper="3.141592653589793" velocity="7.4874625"/>
  </joint>
</robot>
